Workbook

Sheet Matriz Criterios
A1: MATRIZ DE SELECCIÓN DE CRITERIOS DE EVALUACIÓN POR TAREA — DISEÑO DE INTERFACES WEB (2º DAW)
A2: Marca con una 'X' en la casilla correspondiente para activar los criterios evaluados en cada tarea. Los porcentajes de las líneas 52 y 53 se calculan automáticamente.
A4: CRITERIOS OFICIALES DE EVALUACIÓN (ORDEN DE 16 DE JUNIO DE 2011 & DECRETO 104/2024) | H4: 1er TRIMESTRE (T1) — TAREAS Y PRUEBAS | O4: 2º TRIMESTRE (T2) — TAREAS, PRUEBAS Y PROYECTO | W4: Pond. CE Oficial
A5: RA | B5: Peso RA | C5: Código CE | D5: Descripción Oficial del Criterio de Evaluación | E5: UDs | F5: Total Tareas | G5: Estado Cobertura | H5: T01 Figma & Estilos | I5: T02 HTML & CSS Pro | J5: T03 Flexbox & Grid | K5: T04 Responsive & TW4 | L5: T05 Multimedia & Legal | M5: T06 Examen Práctico T1 | N5: T07 Git & W3C T1 | O5: T08 Interactividad CSS | P5: T09 Angular Signals | Q5: T10 Servicios & Forms | R5: T11 Accesibilidad WCAG | S5: T12 Usabilidad & SUS | T5: T13 Proyecto Web SPA | U5: T14 Examen Práctico T2 | V5: T15 Git & Despliegue T2
A6: RA1 | B6: 0.12 | C6: CE1.a | D6: Se ha reconocido la importancia de la comunicación visual y sus principios básicos. | E6: UD01, UD02 | F6: =COUNTIF(H6:V6, "X") | G6: =IF(F6>0, "EVALUADO", "SIN EVALUAR") | H6: X | M6: X | T6: X | W6: 0.02
A7: RA1 | B7: 0.12 | C7: CE1.b | D7: Se han analizado y seleccionado los colores y tipografías adecuados para pantalla. | E7: UD03 | F7: =COUNTIF(H7:V7, "X") | G7: =IF(F7>0, "EVALUADO", "SIN EVALUAR") | H7: X | M7: X | T7: X | W7: 0.02
A8: RA1 | B8: 0.12 | C8: CE1.c | D8: Se han analizado alternativas para la presentación de información web. | E8: UD01, UD06 | F8: =COUNTIF(H8:V8, "X") | G8: =IF(F8>0, "EVALUADO", "SIN EVALUAR") | H8: X | M8: X | T8: X | W8: 0.02
A9: RA1 | B9: 0.12 | C9: CE1.d | D9: Se ha valorado la importancia de definir y aplicar la guía de estilo. | E9: UD04 | F9: =COUNTIF(H9:V9, "X") | G9: =IF(F9>0, "EVALUADO", "SIN EVALUAR") | H9: X | M9: X | N9: X | T9: X | W9: 0.02
A10: RA1 | B10: 0.12 | C10: CE1.e | D10: Se han utilizado y valorado distintas tecnologías para el diseño web. | E10: UD01, UD05 | F10: =COUNTIF(H10:V10, "X") | G10: =IF(F10>0, "EVALUADO", "SIN EVALUAR") | H10: X | M10: X | T10: X | W10: 0.02
A11: RA1 | B11: 0.12 | C11: CE1.f | D11: Se han creado y utilizado plantillas y prototipos de diseño (Figma). | E11: UD05, UD06 | F11: =COUNTIF(H11:V11, "X") | G11: =IF(F11>0, "EVALUADO", "SIN EVALUAR") | H11: X | M11: X | N11: X | T11: X | W11: 0.02
A12: RA2 | B12: 0.2 | C12: CE2.a | D12: Se han reconocido las posibilidades de modificar las etiquetas HTML. | E12: UD07 | F12: =COUNTIF(H12:V12, "X") | G12: =IF(F12>0, "EVALUADO", "SIN EVALUAR") | I12: X | M12: X | W12: 0.02
A13: RA2 | B13: 0.2 | C13: CE2.b | D13: Se han definido estilos de forma directa. | E13: UD08 | F13: =COUNTIF(H13:V13, "X") | G13: =IF(F13>0, "EVALUADO", "SIN EVALUAR") | I13: X | M13: X | W13: 0.02
A14: RA2 | B14: 0.2 | C14: CE2.c | D14: Se han definido y asociado estilos globales en hojas externas. | E14: UD08 | F14: =COUNTIF(H14:V14, "X") | G14: =IF(F14>0, "EVALUADO", "SIN EVALUAR") | I14: X | M14: X | T14: X | W14: 0.02
A15: RA2 | B15: 0.2 | C15: CE2.d | D15: Se han definido hojas de estilos alternativas. | E15: UD08 | F15: =COUNTIF(H15:V15, "X") | G15: =IF(F15>0, "EVALUADO", "SIN EVALUAR") | I15: X | W15: 0.02
A16: RA2 | B16: 0.2 | C16: CE2.e | D16: Se han redefinido estilos (cascada, especificidad, @layer). | E16: UD08, UD09 | F16: =COUNTIF(H16:V16, "X") | G16: =IF(F16>0, "EVALUADO", "SIN EVALUAR") | I16: X | J16: X | M16: X | W16: 0.02
A17: RA2 | B17: 0.2 | C17: CE2.f | D17: Se han identificado las distintas propiedades de cada elemento. | E17: UD08, UD09, UD10 | F17: =COUNTIF(H17:V17, "X") | G17: =IF(F17>0, "EVALUADO", "SIN EVALUAR") | I17: X | J17: X | M17: X | W17: 0.02
A18: RA2 | B18: 0.2 | C18: CE2.g | D18: Se han creado clases y selectores de estilos (BEM). | E18: UD08, UD10 | F18: =COUNTIF(H18:V18, "X") | G18: =IF(F18>0, "EVALUADO", "SIN EVALUAR") | I18: X | J18: X | M18: X | T18: X | W18: 0.02
A19: RA2 | B19: 0.2 | C19: CE2.h | D19: Se han utilizado herramientas de validación de hojas de estilos (W3C). | E19: UD08 | F19: =COUNTIF(H19:V19, "X") | G19: =IF(F19>0, "EVALUADO", "SIN EVALUAR") | I19: X | K19: X | N19: X | V19: X | W19: 0.02
A20: RA2 | B20: 0.2 | C20: CE2.i | D20: Se han utilizado tecnologías y frameworks responsive (Grid, Tailwind 4). | E20: UD10, UD11, UD17 | F20: =COUNTIF(H20:V20, "X") | G20: =IF(F20>0, "EVALUADO", "SIN EVALUAR") | J20: X | K20: X | M20: X | T20: X | U20: X | W20: 0.02
A21: RA2 | B21: 0.2 | C21: CE2.j | D21: Se han analizado y utilizado preprocesadores de estilos (Sass/SCSS). | E21: UD18 | F21: =COUNTIF(H21:V21, "X") | G21: =IF(F21>0, "EVALUADO", "SIN EVALUAR") | K21: X | T21: X | W21: 0.02
A22: RA3 | B22: 0.16 | C22: CE3.a | D22: Se han reconocido las implicaciones de licencias y derechos de autor (TRLPI/CC). | E22: UD19 | F22: =COUNTIF(H22:V22, "X") | G22: =IF(F22>0, "EVALUADO", "SIN EVALUAR") | L22: X | M22: X | W22: 0.02
A23: RA3 | B23: 0.16 | C23: CE3.b | D23: Se han identificado formatos de imagen, audio y vídeo (WebP, AVIF, SVG). | E23: UD12 | F23: =COUNTIF(H23:V23, "X") | G23: =IF(F23>0, "EVALUADO", "SIN EVALUAR") | L23: X | M23: X | T23: X | W23: 0.02
A24: RA3 | B24: 0.16 | C24: CE3.c | D24: Se han analizado herramientas para generar contenido multimedia. | E24: UD12 | F24: =COUNTIF(H24:V24, "X") | G24: =IF(F24>0, "EVALUADO", "SIN EVALUAR") | L24: X | W24: 0.02
A25: RA3 | B25: 0.16 | C25: CE3.d | D25: Se han empleado herramientas para el tratamiento digital de la imagen. | E25: UD12 | F25: =COUNTIF(H25:V25, "X") | G25: =IF(F25>0, "EVALUADO", "SIN EVALUAR") | L25: X | T25: X | W25: 0.02
A26: RA3 | B26: 0.16 | C26: CE3.e | D26: Se han utilizado herramientas para manipular audio y vídeo (HTML5 track). | E26: UD12 | F26: =COUNTIF(H26:V26, "X") | G26: =IF(F26>0, "EVALUADO", "SIN EVALUAR") | L26: X | T26: X | W26: 0.02
A27: RA3 | B27: 0.16 | C27: CE3.f | D27: Se han realizado animaciones a partir de imágenes fijas. | E27: UD12, UD13 | F27: =COUNTIF(H27:V27, "X") | G27: =IF(F27>0, "EVALUADO", "SIN EVALUAR") | L27: X | O27: X | T27: X | W27: 0.02
A28: RA3 | B28: 0.16 | C28: CE3.g | D28: Se han importado y exportado recursos multimedia en diversos formatos. | E28: UD12 | F28: =COUNTIF(H28:V28, "X") | G28: =IF(F28>0, "EVALUADO", "SIN EVALUAR") | L28: X | T28: X | W28: 0.02
A29: RA3 | B29: 0.16 | C29: CE3.h | D29: Se ha aplicado la guía de estilo al material multimedia. | E29: UD04, UD12 | F29: =COUNTIF(H29:V29, "X") | G29: =IF(F29>0, "EVALUADO", "SIN EVALUAR") | L29: X | N29: X | T29: X | W29: 0.02
A30: RA4 | B30: 0.24 | C30: CE4.a | D30: Se han reconocido tecnologías de inclusión de contenido interactivo. | E30: UD13 | F30: =COUNTIF(H30:V30, "X") | G30: =IF(F30>0, "EVALUADO", "SIN EVALUAR") | O30: X | T30: X | W30: 0.02
A31: RA4 | B31: 0.24 | C31: CE4.b | D31: Se han configurado navegadores para contenido multimedia e interactivo. | E31: UD13 | F31: =COUNTIF(H31:V31, "X") | G31: =IF(F31>0, "EVALUADO", "SIN EVALUAR") | O31: X | W31: 0.02
A32: RA4 | B32: 0.24 | C32: CE4.c | D32: Se han utilizado herramientas gráficas para contenido interactivo. | E32: UD13, UD21 | F32: =COUNTIF(H32:V32, "X") | G32: =IF(F32>0, "EVALUADO", "SIN EVALUAR") | O32: X | P32: X | T32: X | W32: 0.04
A33: RA4 | B33: 0.24 | C33: CE4.d | D33: Se ha analizado el código generado por herramientas interactivas. | E33: UD13, UD21, UD22 | F33: =COUNTIF(H33:V33, "X") | G33: =IF(F33>0, "EVALUADO", "SIN EVALUAR") | O33: X | P33: X | Q33: X | T33: X | U33: X | W33: 0.04
A34: RA4 | B34: 0.24 | C34: CE4.e | D34: Se han agregado elementos multimedia a documentos web. | E34: UD12, UD13 | F34: =COUNTIF(H34:V34, "X") | G34: =IF(F34>0, "EVALUADO", "SIN EVALUAR") | O34: X | T34: X | W34: 0.04
A35: RA4 | B35: 0.24 | C35: CE4.f | D35: Se ha añadido interactividad a elementos web (Signals, Events, Forms). | E35: UD13, UD21, UD23 | F35: =COUNTIF(H35:V35, "X") | G35: =IF(F35>0, "EVALUADO", "SIN EVALUAR") | O35: X | P35: X | Q35: X | T35: X | U35: X | W35: 0.04
A36: RA4 | B36: 0.24 | C36: CE4.g | D36: Se ha verificado el funcionamiento interactivo en múltiples dispositivos. | E36: UD11, UD13, UD23 | F36: =COUNTIF(H36:V36, "X") | G36: =IF(F36>0, "EVALUADO", "SIN EVALUAR") | O36: X | Q36: X | T36: X | U36: X | V36: X | W36: 0.04
A37: RA5 | B37: 0.16 | C37: CE5.a | D37: Se ha reconocido la necesidad de diseñar webs accesibles (RD 1112/2018). | E37: UD14 | F37: =COUNTIF(H37:V37, "X") | G37: =IF(F37>0, "EVALUADO", "SIN EVALUAR") | R37: X | T37: X | W37: 0.02
A38: RA5 | B38: 0.16 | C38: CE5.b | D38: Se ha analizado la accesibilidad de diferentes documentos web. | E38: UD14 | F38: =COUNTIF(H38:V38, "X") | G38: =IF(F38>0, "EVALUADO", "SIN EVALUAR") | R38: X | T38: X | W38: 0.02
A39: RA5 | B39: 0.16 | C39: CE5.c | D39: Se han analizado los principios y pautas WCAG 2.2 y niveles de conformidad. | E39: UD14 | F39: =COUNTIF(H39:V39, "X") | G39: =IF(F39>0, "EVALUADO", "SIN EVALUAR") | R39: X | T39: X | U39: X | W39: 0.02
A40: RA5 | B40: 0.16 | C40: CE5.d | D40: Se han analizado los posibles errores según prioridades de verificación. | E40: UD14 | F40: =COUNTIF(H40:V40, "X") | G40: =IF(F40>0, "EVALUADO", "SIN EVALUAR") | R40: X | T40: X | W40: 0.02
A41: RA5 | B41: 0.16 | C41: CE5.e | D41: Se ha alcanzado el nivel de conformidad deseado (Nivel AA/AAA). | E41: UD14 | F41: =COUNTIF(H41:V41, "X") | G41: =IF(F41>0, "EVALUADO", "SIN EVALUAR") | R41: X | T41: X | W41: 0.02
...

Sheet Registro Notas
A1: REGISTRO DE CALIFICACIONES POR TAREA — DISEÑO DE INTERFACES WEB (2º DAW)
A2: Introduce las notas obtenidas (0 a 10). Las cabeceras muestran el % dinámico calculado a partir de los criterios seleccionados en 'Matriz Criterios'.
A4: DATOS DEL ALUMNADO | D4: TAREAS 1er TRIMESTRE (T1) — PESOS DERIVADOS DE CRITERIOS | K4: TAREAS 2º TRIMESTRE (T2) — PESOS DERIVADOS DE CRITERIOS | S4: CALIFICACIONES TRIMESTRALES
A5: Nº | B5: Apellidos, Nombre | C5: Grupo | D5: T01 Figma & Estilos | E5: T02 HTML & CSS Pro | F5: T03 Flex & Grid | G5: T04 Resp. & TW4 | H5: T05 Multimedia | I5: T06 Examen T1 | J5: T07 Git & W3C T1 | K5: T08 Interactividad | L5: T09 Angular Signals | M5: T10 Servicios & Forms | N5: T11 Accesib. WCAG | O5: T12 Usabilidad SUS | P5: T13 Proyecto SPA | Q5: T14 Examen T2 | R5: T15 Git & Despliegue | S5: 1º TRIMESTRE (100% Criterios) | T5: 2º TRIMESTRE (100% Criterios)
A6: 1 | B6: Álvarez Gómez, Laura | C6: 2º DAW | D6: 8.5 | E6: 9 | F6: 8.5 | G6: 8.5 | H6: 9 | I6: 8.5 | J6: 9 | K6: 8.5 | L6: 9 | M6: 8.5 | N6: 9 | O6: 8.5 | P6: 9 | Q6: 8.5 | R6: 9.5 | S6: =D6*'Matriz Criterios'!H$53 + E6*'Matriz Criterios'!I$53 + F6*'Matriz Criterios'!J$53 + G6*'Matriz Criterios'!K$53 + H6*'Matriz Criterios'!L$53 + I6*'Matriz Criterios'!M$53 + J6*'Matriz Criterios'!N$53 | T6: =K6*'Matriz Criterios'!O$53 + L6*'Matriz Criterios'!P$53 + M6*'Matriz Criterios'!Q$53 + N6*'Matriz Criterios'!R$53 + O6*'Matriz Criterios'!S$53 + P6*'Matriz Criterios'!T$53 + Q6*'Matriz Criterios'!U$53 + R6*'Matriz Criterios'!V$53
A7: 2 | B7: Benítez Romero, Carlos | C7: 2º DAW | D7: 6 | E7: 6 | F7: 6.5 | G7: 7 | H7: 6 | I7: 6 | J7: 7 | K7: 6.5 | L7: 6 | M7: 7 | N7: 6.5 | O7: 6 | P7: 6.5 | Q7: 6 | R7: 7 | S7: =D7*'Matriz Criterios'!H$53 + E7*'Matriz Criterios'!I$53 + F7*'Matriz Criterios'!J$53 + G7*'Matriz Criterios'!K$53 + H7*'Matriz Criterios'!L$53 + I7*'Matriz Criterios'!M$53 + J7*'Matriz Criterios'!N$53 | T7: =K7*'Matriz Criterios'!O$53 + L7*'Matriz Criterios'!P$53 + M7*'Matriz Criterios'!Q$53 + N7*'Matriz Criterios'!R$53 + O7*'Matriz Criterios'!S$53 + P7*'Matriz Criterios'!T$53 + Q7*'Matriz Criterios'!U$53 + R7*'Matriz Criterios'!V$53
A8: 3 | B8: Castillo Morales, Elena | C8: 2º DAW | D8: 9.5 | E8: 9 | F8: 10 | G8: 9.5 | H8: 10 | I8: 9.5 | J8: 10 | K8: 10 | L8: 9.5 | M8: 9.5 | N8: 10 | O8: 9.5 | P8: 10 | Q8: 10 | R8: 10 | S8: =D8*'Matriz Criterios'!H$53 + E8*'Matriz Criterios'!I$53 + F8*'Matriz Criterios'!J$53 + G8*'Matriz Criterios'!K$53 + H8*'Matriz Criterios'!L$53 + I8*'Matriz Criterios'!M$53 + J8*'Matriz Criterios'!N$53 | T8: =K8*'Matriz Criterios'!O$53 + L8*'Matriz Criterios'!P$53 + M8*'Matriz Criterios'!Q$53 + N8*'Matriz Criterios'!R$53 + O8*'Matriz Criterios'!S$53 + P8*'Matriz Criterios'!T$53 + Q8*'Matriz Criterios'!U$53 + R8*'Matriz Criterios'!V$53
A9: 4 | B9: Delgado Santos, Alejandro | C9: 2º DAW | D9: 4.5 | E9: 5 | F9: 4.5 | G9: 5.5 | H9: 4 | I9: 4.5 | J9: 6 | K9: 5 | L9: 4.5 | M9: 5 | N9: 4.5 | O9: 5 | P9: 4.5 | Q9: 4 | R9: 5 | S9: =D9*'Matriz Criterios'!H$53 + E9*'Matriz Criterios'!I$53 + F9*'Matriz Criterios'!J$53 + G9*'Matriz Criterios'!K$53 + H9*'Matriz Criterios'!L$53 + I9*'Matriz Criterios'!M$53 + J9*'Matriz Criterios'!N$53 | T9: =K9*'Matriz Criterios'!O$53 + L9*'Matriz Criterios'!P$53 + M9*'Matriz Criterios'!Q$53 + N9*'Matriz Criterios'!R$53 + O9*'Matriz Criterios'!S$53 + P9*'Matriz Criterios'!T$53 + Q9*'Matriz Criterios'!U$53 + R9*'Matriz Criterios'!V$53
A10: 5 | B10: Fernández Navarro, Lucía | C10: 2º DAW | D10: 7.5 | E10: 8 | F10: 7 | G10: 7.5 | H10: 8 | I10: 7.5 | J10: 8.5 | K10: 7.5 | L10: 8 | M10: 8 | N10: 7.5 | O10: 8 | P10: 7.5 | Q10: 8 | R10: 8.5 | S10: =D10*'Matriz Criterios'!H$53 + E10*'Matriz Criterios'!I$53 + F10*'Matriz Criterios'!J$53 + G10*'Matriz Criterios'!K$53 + H10*'Matriz Criterios'!L$53 + I10*'Matriz Criterios'!M$53 + J10*'Matriz Criterios'!N$53 | T10: =K10*'Matriz Criterios'!O$53 + L10*'Matriz Criterios'!P$53 + M10*'Matriz Criterios'!Q$53 + N10*'Matriz Criterios'!R$53 + O10*'Matriz Criterios'!S$53 + P10*'Matriz Criterios'!T$53 + Q10*'Matriz Criterios'!U$53 + R10*'Matriz Criterios'!V$53
A11: 6 | B11: García Serrano, David | C11: 2º DAW | D11: 8 | E11: 7.5 | F11: 8.5 | G11: 8 | H11: 8.5 | I11: 8 | J11: 8.5 | K11: 8 | L11: 8.5 | M11: 8 | N11: 8.5 | O11: 8 | P11: 8.5 | Q11: 8 | R11: 8.5 | S11: =D11*'Matriz Criterios'!H$53 + E11*'Matriz Criterios'!I$53 + F11*'Matriz Criterios'!J$53 + G11*'Matriz Criterios'!K$53 + H11*'Matriz Criterios'!L$53 + I11*'Matriz Criterios'!M$53 + J11*'Matriz Criterios'!N$53 | T11: =K11*'Matriz Criterios'!O$53 + L11*'Matriz Criterios'!P$53 + M11*'Matriz Criterios'!Q$53 + N11*'Matriz Criterios'!R$53 + O11*'Matriz Criterios'!S$53 + P11*'Matriz Criterios'!T$53 + Q11*'Matriz Criterios'!U$53 + R11*'Matriz Criterios'!V$53
A12: 7 | B12: Herrera Cruz, Marta | C12: 2º DAW | D12: 9 | E12: 8.5 | F12: 9.5 | G12: 9 | H12: 9 | I12: 9 | J12: 9.5 | K12: 9 | L12: 9.5 | M12: 9 | N12: 9.5 | O12: 9 | P12: 9.5 | Q12: 9 | R12: 9.5 | S12: =D12*'Matriz Criterios'!H$53 + E12*'Matriz Criterios'!I$53 + F12*'Matriz Criterios'!J$53 + G12*'Matriz Criterios'!K$53 + H12*'Matriz Criterios'!L$53 + I12*'Matriz Criterios'!M$53 + J12*'Matriz Criterios'!N$53 | T12: =K12*'Matriz Criterios'!O$53 + L12*'Matriz Criterios'!P$53 + M12*'Matriz Criterios'!Q$53 + N12*'Matriz Criterios'!R$53 + O12*'Matriz Criterios'!S$53 + P12*'Matriz Criterios'!T$53 + Q12*'Matriz Criterios'!U$53 + R12*'Matriz Criterios'!V$53
A13: 8 | B13: Jiménez Ortiz, Pablo | C13: 2º DAW | D13: 5.5 | E13: 6 | F13: 5.5 | G13: 5 | H13: 6 | I13: 5.5 | J13: 6.5 | K13: 5.5 | L13: 6 | M13: 5.5 | N13: 6 | O13: 5.5 | P13: 6 | Q13: 5.5 | R13: 6.5 | S13: =D13*'Matriz Criterios'!H$53 + E13*'Matriz Criterios'!I$53 + F13*'Matriz Criterios'!J$53 + G13*'Matriz Criterios'!K$53 + H13*'Matriz Criterios'!L$53 + I13*'Matriz Criterios'!M$53 + J13*'Matriz Criterios'!N$53 | T13: =K13*'Matriz Criterios'!O$53 + L13*'Matriz Criterios'!P$53 + M13*'Matriz Criterios'!Q$53 + N13*'Matriz Criterios'!R$53 + O13*'Matriz Criterios'!S$53 + P13*'Matriz Criterios'!T$53 + Q13*'Matriz Criterios'!U$53 + R13*'Matriz Criterios'!V$53
A14: 9 | B14: López Molina, Sara | C14: 2º DAW | D14: 10 | E14: 9.5 | F14: 9.5 | G14: 10 | H14: 9.5 | I14: 10 | J14: 10 | K14: 10 | L14: 9.5 | M14: 10 | N14: 10 | O14: 9.5 | P14: 10 | Q14: 10 | R14: 10 | S14: =D14*'Matriz Criterios'!H$53 + E14*'Matriz Criterios'!I$53 + F14*'Matriz Criterios'!J$53 + G14*'Matriz Criterios'!K$53 + H14*'Matriz Criterios'!L$53 + I14*'Matriz Criterios'!M$53 + J14*'Matriz Criterios'!N$53 | T14: =K14*'Matriz Criterios'!O$53 + L14*'Matriz Criterios'!P$53 + M14*'Matriz Criterios'!Q$53 + N14*'Matriz Criterios'!R$53 + O14*'Matriz Criterios'!S$53 + P14*'Matriz Criterios'!T$53 + Q14*'Matriz Criterios'!U$53 + R14*'Matriz Criterios'!V$53
A15: 10 | B15: Martín Vega, Javier | C15: 2º DAW | D15: 3.5 | E15: 4 | F15: 4 | G15: 4.5 | H15: 4 | I15: 3.5 | J15: 5 | K15: 4 | L15: 4.5 | M15: 4 | N15: 4 | O15: 4.5 | P15: 4 | Q15: 4 | R15: 4.5 | S15: =D15*'Matriz Criterios'!H$53 + E15*'Matriz Criterios'!I$53 + F15*'Matriz Criterios'!J$53 + G15*'Matriz Criterios'!K$53 + H15*'Matriz Criterios'!L$53 + I15*'Matriz Criterios'!M$53 + J15*'Matriz Criterios'!N$53 | T15: =K15*'Matriz Criterios'!O$53 + L15*'Matriz Criterios'!P$53 + M15*'Matriz Criterios'!Q$53 + N15*'Matriz Criterios'!R$53 + O15*'Matriz Criterios'!S$53 + P15*'Matriz Criterios'!T$53 + Q15*'Matriz Criterios'!U$53 + R15*'Matriz Criterios'!V$53
A16: 11 | B16: Navarro Gil, Ana | C16: 2º DAW | D16: 8 | E16: 8.5 | F16: 8 | G16: 8.5 | H16: 8 | I16: 8.5 | J16: 9 | K16: 8.5 | L16: 8 | M16: 8.5 | N16: 8.5 | O16: 8 | P16: 8.5 | Q16: 8.5 | R16: 9 | S16: =D16*'Matriz Criterios'!H$53 + E16*'Matriz Criterios'!I$53 + F16*'Matriz Criterios'!J$53 + G16*'Matriz Criterios'!K$53 + H16*'Matriz Criterios'!L$53 + I16*'Matriz Criterios'!M$53 + J16*'Matriz Criterios'!N$53 | T16: =K16*'Matriz Criterios'!O$53 + L16*'Matriz Criterios'!P$53 + M16*'Matriz Criterios'!Q$53 + N16*'Matriz Criterios'!R$53 + O16*'Matriz Criterios'!S$53 + P16*'Matriz Criterios'!T$53 + Q16*'Matriz Criterios'!U$53 + R16*'Matriz Criterios'!V$53
A17: 12 | B17: Pérez Rubio, Álvaro | C17: 2º DAW | D17: 7 | E17: 6.5 | F17: 7.5 | G17: 7 | H17: 7 | I17: 7 | J17: 7.5 | K17: 7.5 | L17: 7 | M17: 7.5 | N17: 7 | O17: 7.5 | P17: 7 | Q17: 7.5 | R17: 7.5 | S17: =D17*'Matriz Criterios'!H$53 + E17*'Matriz Criterios'!I$53 + F17*'Matriz Criterios'!J$53 + G17*'Matriz Criterios'!K$53 + H17*'Matriz Criterios'!L$53 + I17*'Matriz Criterios'!M$53 + J17*'Matriz Criterios'!N$53 | T17: =K17*'Matriz Criterios'!O$53 + L17*'Matriz Criterios'!P$53 + M17*'Matriz Criterios'!Q$53 + N17*'Matriz Criterios'!R$53 + O17*'Matriz Criterios'!S$53 + P17*'Matriz Criterios'!T$53 + Q17*'Matriz Criterios'!U$53 + R17*'Matriz Criterios'!V$53
... A20: 15 | B20: Torres Lozano, Irene | C20: 2º DAW | D20: 9 | E20: 9.5 | F20: 9 | G20: 9.5 | H20: 9 | I20: 9.5 | J20: 9.5 | K20: 9.5 | L20: 9 | M20: 9.5 | N20: 10 | O20: 9.5 | P20: 9.5 | Q20: 9.5 | R20: 10 | S20: =D20*'Matriz Criterios'!H$53 + E20*'Matriz Criterios'!I$53 + F20*'Matriz Criterios'!J$53 + G20*'Matriz Criterios'!K$53 + H20*'Matriz Criterios'!L$53 + I20*'Matriz Criterios'!M$53 + J20*'Matriz Criterios'!N$53 | T20: =K20*'Matriz Criterios'!O$53 + L20*'Matriz Criterios'!P$53 + M20*'Matriz Criterios'!Q$53 + N20*'Matriz Criterios'!R$53 + O20*'Matriz Criterios'!S$53 + P20*'Matriz Criterios'!T$53 + Q20*'Matriz Criterios'!U$53 + R20*'Matriz Criterios'!V$53
A21: PROMEDIO DEL GRUPO | D21: =AVERAGE(D6:D20) | E21: =AVERAGE(E6:E20) | F21: =AVERAGE(F6:F20) | G21: =AVERAGE(G6:G20) | H21: =AVERAGE(H6:H20) | I21: =AVERAGE(I6:I20) | J21: =AVERAGE(J6:J20) | K21: =AVERAGE(K6:K20) | ... T21: =AVERAGE(T6:T20)

Sheet Calculo CEs
A1: CALIFICACIÓN DETALLADA POR CRITERIOS DE EVALUACIÓN (CE1.a a CE6.f) — DISEÑO DE INTERFACES WEB
A2: Cálculo matemático automático: cada criterio se calcula promediando exclusivamente las tareas donde tiene marcada una 'X' en la 'Matriz Criterios'.
A4: ALUMNADO | C4: RA1 (12%) — Planificación, Prototipado, Color, Tipografía y Guía de Estilo | I4: RA2 (20%) — HTML Semántico, CSS Moderno, Flexbox, Grid, Responsive y Preprocesadores | S4: RA3 (16%) — Multimedia Web, Formatos (WebP, SVG), Audio/Vídeo y Marco Legal TRLPI | AA4: RA4 (24%) — Interactividad, Animaciones, Framework Frontend Angular y Formularios | AH4: RA5 (16%) — Accesibilidad Web Universal (WCAG 2.2, WAI-ARIA) y Auditorías | AP4: RA6 (12%) — Usabilidad Web, Heurísticas de Nielsen, Métricas SUS y DCU | AV4: RESUMEN DE CRITERIOS
A5: Nº | B5: Apellidos, Nombre | C5: CE1.a | D5: CE1.b | E5: CE1.c | F5: CE1.d | G5: CE1.e | H5: CE1.f | I5: CE2.a | J5: CE2.b | K5: CE2.c | L5: CE2.d | M5: CE2.e | N5: CE2.f | O5: CE2.g | P5: CE2.h | Q5: CE2.i | R5: CE2.j | S5: CE3.a | T5: CE3.b | U5: CE3.c | V5: CE3.d | W5: CE3.e | X5: CE3.f | Y5: CE3.g | Z5: CE3.h | AA5: CE4.a | AB5: CE4.b | AC5: CE4.c | AD5: CE4.d | AE5: CE4.e | AF5: CE4.f | AG5: CE4.g | AH5: CE5.a | AI5: CE5.b | AJ5: CE5.c | AK5: CE5.d | AL5: CE5.e | AM5: CE5.f | AN5: CE5.g | AO5: CE5.h | AP5: CE6.a | AQ5: CE6.b | AR5: CE6.c | AS5: CE6.d | AT5: CE6.e | AU5: CE6.f | AV5: Media CEs Superados | AW5: Nº CEs >= 5 (de 45)
A6: 1 | B6: Álvarez Gómez, Laura | C6: =IF(SUMPRODUCT(('Matriz Criterios'!$H$6:$V$6="X")*ISNUMBER('Registro Notas'!$D6:$R6))=0, "-", SUMPRODUCT(('Matriz Criterios'!$H$6:$V$6="X")*ISNUMBER('Registro Notas'!$D6:$R6)*'Registro Notas'!$D6:$R6)/SUMPRODUCT(('Matriz Criterios'!$H$6:$V$6="X")*ISNUMBER('Registro Notas'!$D6:$R6))) | D6: =IF(SUMPRODUCT(('Matriz Criterios'!$H$7:$V$7="X")*ISNUMBER('Registro Notas'!$D6:$R6))=0, "-", SUMPRODUCT(('Matriz Criterios'!$H$7:$V$7="X")*ISNUMBER('Registro Notas'!$D6:$R6)*'Registro Notas'!$D6:$R6)/SUMPRODUCT(('Matriz Criterios'!$H$7:$V$7="X")*ISNUMBER('Registro Notas'!$D6:$R6))) | E6: =IF(SUMPRODUCT(('Matriz Criterios'!$H$8:$V$8="X")*ISNUMBER('Registro Notas'!$D6:$R6))=0, "-", SUMPRODUCT(('Matriz Criterios'!$H$8:$V$8="X")*ISNUMBER('Registro Notas'!$D6:$R6)*'Registro Notas'!$D6:$R6)/SUMPRODUCT(('Matriz Criterios'!$H$8:$V$8="X")*ISNUMBER('Registro Notas'!$D6:$R6))) | F6: =IF(SUMPRODUCT(('Matriz Criterios'!$H$9:$V$9="X")*ISNUMBER('Registro Notas'!$D6:$R6))=0, "-", SUMPRODUCT(('Matriz Criterios'!$H$9:$V$9="X")*ISNUMBER('Registro Notas'!$D6:$R6)*'Registro Notas'!$D6:$R6)/SUMPRODUCT(('Matriz Criterios'!$H$9:$V$9="X")*ISNUMBER('Registro Notas'!$D6:$R6))) | G6: =IF(SUMPRODUCT(('Matriz Criterios'!$H$10:$V$10="X")*ISNUMBER('Registro Notas'!$D6:$R6))=0, "-", SUMPRODUCT(('Matriz Criterios'!$H$10:$V$10="X")*ISNUMBER('Registro Notas'!$D6:$R6)*'Registro Notas'!$D6:$R6)/SUMPRODUCT(('Matriz Criterios'!$H$10:$V$10="X")*ISNUMBER('Registro Notas'!$D6:$R6))) | H6: =IF(SUMPRODUCT(('Matriz Criterios'!$H$11:$V$11="X")*ISNUMBER('Registro Notas'!$D6:$R6))=0, "-", SUMPRODUCT(('Matriz Criterios'!$H$11:$V$11="X")*ISNUMBER('Registro Notas'!$D6:$R6)*'Registro Notas'!$D6:$R6)/SUMPRODUCT(('Matriz Criterios'!$H$11:$V$11="X")*ISNUMBER('Registro Notas'!$D6:$R6))) | I6: =IF(SUMPRODUCT(('Matriz Criterios'!$H$12:$V$12="X")*ISNUMBER('Registro Notas'!$D6:$R6))=0, "-", SUMPRODUCT(('Matriz Criterios'!$H$12:$V$12="X")*ISNUMBER('Registro Notas'!$D6:$R6)*'Registro Notas'!$D6:$R6)/SUMPRODUCT(('Matriz Criterios'!$H$12:$V$12="X")*ISNUMBER('Registro Notas'!$D6:$R6))) | J6: =IF(SUMPRODUCT(('Matriz Criterios'!$H$13:$V$13="X")*ISNUMBER('Registro Notas'!$D6:$R6))=0, "-", SUMPRODUCT(('Matriz Criterios'!$H$13:$V$13="X")*ISNUMBER('Registro Notas'!$D6:$R6)*'Registro Notas'!$D6:$R6)/SUMPRODUCT(('Matriz Criterios'!$H$13:$V$13="X")*ISNUMBER('Registro Notas'!$D6:$R6))) | K6: =IF(SUMPRODUCT(('Matriz Criterios'!$H$14:$V$14="X")*ISNUMBER('Registro Notas'!$D6:$R6))=0, "-", SUMPRODUCT(('Matriz Criterios'!$H$14:$V$14="X")*ISNUMBER('Registro Notas'!$D6:$R6)*'Registro Notas'!$D6:$R6)/SUMPRODUCT(('Matriz Criterios'!$H$14:$V$14="X")*ISNUMBER('Registro Notas'!$D6:$R6))) | L6: =IF(SUMPRODUCT(('Matriz Criterios'!$H$15:$V$15="X")*ISNUMBER('Registro Notas'!$D6:$R6))=0, "-", SUMPRODUCT(('Matriz Criterios'!$H$15:$V$15="X")*ISNUMBER('Registro Notas'!$D6:$R6)*'Registro Notas'!$D6:$R6)/SUMPRODUCT(('Matriz Criterios'!$H$15:$V$15="X")*ISNUMBER('Registro Notas'!$D6:$R6))) | M6: =IF(SUMPRODUCT(('Matriz Criterios'!$H$16:$V$16="X")*ISNUMBER('Registro Notas'!$D6:$R6))=0, "-", SUMPRODUCT(('Matriz Criterios'!$H$16:$V$16="X")*ISNUMBER('Registro Notas'!$D6:$R6)*'Registro Notas'!$D6:$R6)/SUMPRODUCT(('Matriz Criterios'!$H$16:$V$16="X")*ISNUMBER('Registro Notas'!$D6:$R6))) | N6: =IF(SUMPRODUCT(('Matriz Criterios'!$H$17:$V$17="X")*ISNUMBER('Registro Notas'!$D6:$R6))=0, "-", SUMPRODUCT(('Matriz Criterios'!$H$17:$V$17="X")*ISNUMBER('Registro Notas'!$D6:$R6)*'Registro Notas'!$D6:$R6)/SUMPRODUCT(('Matriz Criterios'!$H$17:$V$17="X")*ISNUMBER('Registro Notas'!$D6:$R6))) | O6: =IF(SUMPRODUCT(('Matriz Criterios'!$H$18:$V$18="X")*ISNUMBER('Registro Notas'!$D6:$R6))=0, "-", SUMPRODUCT(('Matriz Criterios'!$H$18:$V$18="X")*ISNUMBER('Registro Notas'!$D6:$R6)*'Registro Notas'!$D6:$R6)/SUMPRODUCT(('Matriz Criterios'!$H$18:$V$18="X")*ISNUMBER('Registro Notas'!$D6:$R6))) | P6: =IF(SUMPRODUCT(('Matriz Criterios'!$H$19:$V$19="X")*ISNUMBER('Registro Notas'!$D6:$R6))=0, "-", SUMPRODUCT(('Matriz Criterios'!$H$19:$V$19="X")*ISNUMBER('Registro Notas'!$D6:$R6)*'Registro Notas'!$D6:$R6)/SUMPRODUCT(('Matriz Criterios'!$H$19:$V$19="X")*ISNUMBER('Registro Notas'!$D6:$R6))) | Q6: =IF(SUMPRODUCT(('Matriz Criterios'!$H$20:$V$20="X")*ISNUMBER('Registro Notas'!$D6:$R6))=0, "-", SUMPRODUCT(('Matriz Criterios'!$H$20:$V$20="X")*ISNUMBER('Registro Notas'!$D6:$R6)*'Registro Notas'!$D6:$R6)/SUMPRODUCT(('Matriz Criterios'!$H$20:$V$20="X")*ISNUMBER('Registro Notas'!$D6:$R6))) | R6: =IF(SUMPRODUCT(('Matriz Criterios'!$H$21:$V$21="X")*ISNUMBER('Registro Notas'!$D6:$R6))=0, "-", SUMPRODUCT(('Matriz Criterios'!$H$21:$V$21="X")*ISNUMBER('Registro Notas'!$D6:$R6)*'Registro Notas'!$D6:$R6)/SUMPRODUCT(('Matriz Criterios'!$H$21:$V$21="X")*ISNUMBER('Registro Notas'!$D6:$R6))) | S6: =IF(SUMPRODUCT(('Matriz Criterios'!$H$22:$V$22="X")*ISNUMBER('Registro Notas'!$D6:$R6))=0, "-", SUMPRODUCT(('Matriz Criterios'!$H$22:$V$22="X")*ISNUMBER('Registro Notas'!$D6:$R6)*'Registro Notas'!$D6:$R6)/SUMPRODUCT(('Matriz Criterios'!$H$22:$V$22="X")*ISNUMBER('Registro Notas'!$D6:$R6))) | T6: =IF(SUMPRODUCT(('Matriz Criterios'!$H$23:$V$23="X")*ISNUMBER('Registro Notas'!$D6:$R6))=0, "-", SUMPRODUCT(('Matriz Criterios'!$H$23:$V$23="X")*ISNUMBER('Registro Notas'!$D6:$R6)*'Registro Notas'!$D6:$R6)/SUMPRODUCT(('Matriz Criterios'!$H$23:$V$23="X")*ISNUMBER('Registro Notas'!$D6:$R6))) | U6: =IF(SUMPRODUCT(('Matriz Criterios'!$H$24:$V$24="X")*ISNUMBER('Registro Notas'!$D6:$R6))=0, "-", SUMPRODUCT(('Matriz Criterios'!$H$24:$V$24="X")*ISNUMBER('Registro Notas'!$D6:$R6)*'Registro Notas'!$D6:$R6)/SUMPRODUCT(('Matriz Criterios'!$H$24:$V$24="X")*ISNUMBER('Registro Notas'!$D6:$R6))) | V6: =IF(SUMPRODUCT(('Matriz Criterios'!$H$25:$V$25="X")*ISNUMBER('Registro Notas'!$D6:$R6))=0, "-", SUMPRODUCT(('Matriz Criterios'!$H$25:$V$25="X")*ISNUMBER('Registro Notas'!$D6:$R6)*'Registro Notas'!$D6:$R6)/SUMPRODUCT(('Matriz Criterios'!$H$25:$V$25="X")*ISNUMBER('Registro Notas'!$D6:$R6))) | W6: =IF(SUMPRODUCT(('Matriz Criterios'!$H$26:$V$26="X")*ISNUMBER('Registro Notas'!$D6:$R6))=0, "-", SUMPRODUCT(('Matriz Criterios'!$H$26:$V$26="X")*ISNUMBER('Registro Notas'!$D6:$R6)*'Registro Notas'!$D6:$R6)/SUMPRODUCT(('Matriz Criterios'!$H$26:$V$26="X")*ISNUMBER('Registro Notas'!$D6:$R6))) | X6: =IF(SUMPRODUCT(('Matriz Criterios'!$H$27:$V$27="X")*ISNUMBER('Registro Notas'!$D6:$R6))=0, "-", SUMPRODUCT(('Matriz Criterios'!$H$27:$V$27="X")*ISNUMBER('Registro Notas'!$D6:$R6)*'Registro Notas'!$D6:$R6)/SUMPRODUCT(('Matriz Criterios'!$H$27:$V$27="X")*ISNUMBER('Registro Notas'!$D6:$R6))) | Y6: =IF(SUMPRODUCT(('Matriz Criterios'!$H$28:$V$28="X")*ISNUMBER('Registro Notas'!$D6:$R6))=0, "-", SUMPRODUCT(('Matriz Criterios'!$H$28:$V$28="X")*ISNUMBER('Registro Notas'!$D6:$R6)*'Registro Notas'!$D6:$R6)/SUMPRODUCT(('Matriz Criterios'!$H$28:$V$28="X")*ISNUMBER('Registro Notas'!$D6:$R6))) | Z6: =IF(SUMPRODUCT(('Matriz Criterios'!$H$29:$V$29="X")*ISNUMBER('Registro Notas'!$D6:$R6))=0, "-", SUMPRODUCT(('Matriz Criterios'!$H$29:$V$29="X")*ISNUMBER('Registro Notas'!$D6:$R6)*'Registro Notas'!$D6:$R6)/SUMPRODUCT(('Matriz Criterios'!$H$29:$V$29="X")*ISNUMBER('Registro Notas'!$D6:$R6))) | AA6: =IF(SUMPRODUCT(('Matriz Criterios'!$H$30:$V$30="X")*ISNUMBER('Registro Notas'!$D6:$R6))=0, "-", SUMPRODUCT(('Matriz Criterios'!$H$30:$V$30="X")*ISNUMBER('Registro Notas'!$D6:$R6)*'Registro Notas'!$D6:$R6)/SUMPRODUCT(('Matriz Criterios'!$H$30:$V$30="X")*ISNUMBER('Registro Notas'!$D6:$R6))) | AB6: =IF(SUMPRODUCT(('Matriz Criterios'!$H$31:$V$31="X")*ISNUMBER('Registro Notas'!$D6:$R6))=0, "-", SUMPRODUCT(('Matriz Criterios'!$H$31:$V$31="X")*ISNUMBER('Registro Notas'!$D6:$R6)*'Registro Notas'!$D6:$R6)/SUMPRODUCT(('Matriz Criterios'!$H$31:$V$31="X")*ISNUMBER('Registro Notas'!$D6:$R6))) | AC6: =IF(SUMPRODUCT(('Matriz Criterios'!$H$32:$V$32="X")*ISNUMBER('Registro Notas'!$D6:$R6))=0, "-", SUMPRODUCT(('Matriz Criterios'!$H$32:$V$32="X")*ISNUMBER('Registro Notas'!$D6:$R6)*'Registro Notas'!$D6:$R6)/SUMPRODUCT(('Matriz Criterios'!$H$32:$V$32="X")*ISNUMBER('Registro Notas'!$D6:$R6))) | AD6: =IF(SUMPRODUCT(('Matriz Criterios'!$H$33:$V$33="X")*ISNUMBER('Registro Notas'!$D6:$R6))=0, "-", SUMPRODUCT(('Matriz Criterios'!$H$33:$V$33="X")*ISNUMBER('Registro Notas'!$D6:$R6)*'Registro Notas'!$D6:$R6)/SUMPRODUCT(('Matriz Criterios'!$H$33:$V$33="X")*ISNUMBER('Registro Notas'!$D6:$R6))) | AE6: =IF(SUMPRODUCT(('Matriz Criterios'!$H$34:$V$34="X")*ISNUMBER('Registro Notas'!$D6:$R6))=0, "-", SUMPRODUCT(('Matriz Criterios'!$H$34:$V$34="X")*ISNUMBER('Registro Notas'!$D6:$R6)*'Registro Notas'!$D6:$R6)/SUMPRODUCT(('Matriz Criterios'!$H$34:$V$34="X")*ISNUMBER('Registro Notas'!$D6:$R6))) | AF6: =IF(SUMPRODUCT(('Matriz Criterios'!$H$35:$V$35="X")*ISNUMBER('Registro Notas'!$D6:$R6))=0, "-", SUMPRODUCT(('Matriz Criterios'!$H$35:$V$35="X")*ISNUMBER('Registro Notas'!$D6:$R6)*'Registro Notas'!$D6:$R6)/SUMPRODUCT(('Matriz Criterios'!$H$35:$V$35="X")*ISNUMBER('Registro Notas'!$D6:$R6))) | AG6: =IF(SUMPRODUCT(('Matriz Criterios'!$H$36:$V$36="X")*ISNUMBER('Registro Notas'!$D6:$R6))=0, "-", SUMPRODUCT(('Matriz Criterios'!$H$36:$V$36="X")*ISNUMBER('Registro Notas'!$D6:$R6)*'Registro Notas'!$D6:$R6)/SUMPRODUCT(('Matriz Criterios'!$H$36:$V$36="X")*ISNUMBER('Registro Notas'!$D6:$R6))) | AH6: =IF(SUMPRODUCT(('Matriz Criterios'!$H$37:$V$37="X")*ISNUMBER('Registro Notas'!$D6:$R6))=0, "-", SUMPRODUCT(('Matriz Criterios'!$H$37:$V$37="X")*ISNUMBER('Registro Notas'!$D6:$R6)*'Registro Notas'!$D6:$R6)/SUMPRODUCT(('Matriz Criterios'!$H$37:$V$37="X")*ISNUMBER('Registro Notas'!$D6:$R6))) | AI6: =IF(SUMPRODUCT(('Matriz Criterios'!$H$38:$V$38="X")*ISNUMBER('Registro Notas'!$D6:$R6))=0, "-", SUMPRODUCT(('Matriz Criterios'!$H$38:$V$38="X")*ISNUMBER('Registro Notas'!$D6:$R6)*'Registro Notas'!$D6:$R6)/SUMPRODUCT(('Matriz Criterios'!$H$38:$V$38="X")*ISNUMBER('Registro Notas'!$D6:$R6))) | AJ6: =IF(SUMPRODUCT(('Matriz Criterios'!$H$39:$V$39="X")*ISNUMBER('Registro Notas'!$D6:$R6))=0, "-", SUMPRODUCT(('Matriz Criterios'!$H$39:$V$39="X")*ISNUMBER('Registro Notas'!$D6:$R6)*'Registro Notas'!$D6:$R6)/SUMPRODUCT(('Matriz Criterios'!$H$39:$V$39="X")*ISNUMBER('Registro Notas'!$D6:$R6))) | AK6: =IF(SUMPRODUCT(('Matriz Criterios'!$H$40:$V$40="X")*ISNUMBER('Registro Notas'!$D6:$R6))=0, "-", SUMPRODUCT(('Matriz Criterios'!$H$40:$V$40="X")*ISNUMBER('Registro Notas'!$D6:$R6)*'Registro Notas'!$D6:$R6)/SUMPRODUCT(('Matriz Criterios'!$H$40:$V$40="X")*ISNUMBER('Registro Notas'!$D6:$R6))) | AL6: =IF(SUMPRODUCT(('Matriz Criterios'!$H$41:$V$41="X")*ISNUMBER('Registro Notas'!$D6:$R6))=0, "-", SUMPRODUCT(('Matriz Criterios'!$H$41:$V$41="X")*ISNUMBER('Registro Notas'!$D6:$R6)*'Registro Notas'!$D6:$R6)/SUMPRODUCT(('Matriz Criterios'!$H$41:$V$41="X")*ISNUMBER('Registro Notas'!$D6:$R6))) | AM6: =IF(SUMPRODUCT(('Matriz Criterios'!$H$42:$V$42="X")*ISNUMBER('Registro Notas'!$D6:$R6))=0, "-", SUMPRODUCT(('Matriz Criterios'!$H$42:$V$42="X")*ISNUMBER('Registro Notas'!$D6:$R6)*'Registro Notas'!$D6:$R6)/SUMPRODUCT(('Matriz Criterios'!$H$42:$V$42="X")*ISNUMBER('Registro Notas'!$D6:$R6))) | AN6: =IF(SUMPRODUCT(('Matriz Criterios'!$H$43:$V$43="X")*ISNUMBER('Registro Notas'!$D6:$R6))=0, "-", SUMPRODUCT(('Matriz Criterios'!$H$43:$V$43="X")*ISNUMBER('Registro Notas'!$D6:$R6)*'Registro Notas'!$D6:$R6)/SUMPRODUCT(('Matriz Criterios'!$H$43:$V$43="X")*ISNUMBER('Registro Notas'!$D6:$R6))) | AO6: =IF(SUMPRODUCT(('Matriz Criterios'!$H$44:$V$44="X")*ISNUMBER('Registro Notas'!$D6:$R6))=0, "-", SUMPRODUCT(('Matriz Criterios'!$H$44:$V$44="X")*ISNUMBER('Registro Notas'!$D6:$R6)*'Registro Notas'!$D6:$R6)/SUMPRODUCT(('Matriz Criterios'!$H$44:$V$44="X")*ISNUMBER('Registro Notas'!$D6:$R6))) | AP6: =IF(SUMPRODUCT(('Matriz Criterios'!$H$45:$V$45="X")*ISNUMBER('Registro Notas'!$D6:$R6))=0, "-", SUMPRODUCT(('Matriz Criterios'!$H$45:$V$45="X")*ISNUMBER('Registro Notas'!$D6:$R6)*'Registro Notas'!$D6:$R6)/SUMPRODUCT(('Matriz Criterios'!$H$45:$V$45="X")*ISNUMBER('Registro Notas'!$D6:$R6))) | AQ6: =IF(SUMPRODUCT(('Matriz Criterios'!$H$46:$V$46="X")*ISNUMBER('Registro Notas'!$D6:$R6))=0, "-", SUMPRODUCT(('Matriz Criterios'!$H$46:$V$46="X")*ISNUMBER('Registro Notas'!$D6:$R6)*'Registro Notas'!$D6:$R6)/SUMPRODUCT(('Matriz Criterios'!$H$46:$V$46="X")*ISNUMBER('Registro Notas'!$D6:$R6))) | AR6: =IF(SUMPRODUCT(('Matriz Criterios'!$H$47:$V$47="X")*ISNUMBER('Registro Notas'!$D6:$R6))=0, "-", SUMPRODUCT(('Matriz Criterios'!$H$47:$V$47="X")*ISNUMBER('Registro Notas'!$D6:$R6)*'Registro Notas'!$D6:$R6)/SUMPRODUCT(('Matriz Criterios'!$H$47:$V$47="X")*ISNUMBER('Registro Notas'!$D6:$R6))) | AS6: =IF(SUMPRODUCT(('Matriz Criterios'!$H$48:$V$48="X")*ISNUMBER('Registro Notas'!$D6:$R6))=0, "-", SUMPRODUCT(('Matriz Criterios'!$H$48:$V$48="X")*ISNUMBER('Registro Notas'!$D6:$R6)*'Registro Notas'!$D6:$R6)/SUMPRODUCT(('Matriz Criterios'!$H$48:$V$48="X")*ISNUMBER('Registro Notas'!$D6:$R6))) | AT6: =IF(SUMPRODUCT(('Matriz Criterios'!$H$49:$V$49="X")*ISNUMBER('Registro Notas'!$D6:$R6))=0, "-", SUMPRODUCT(('Matriz Criterios'!$H$49:$V$49="X")*ISNUMBER('Registro Notas'!$D6:$R6)*'Registro Notas'!$D6:$R6)/SUMPRODUCT(('Matriz Criterios'!$H$49:$V$49="X")*ISNUMBER('Registro Notas'!$D6:$R6))) | AU6: =IF(SUMPRODUCT(('Matriz Criterios'!$H$50:$V$50="X")*ISNUMBER('Registro Notas'!$D6:$R6))=0, "-", SUMPRODUCT(('Matriz Criterios'!$H$50:$V$50="X")*ISNUMBER('Registro Notas'!$D6:$R6)*'Registro Notas'!$D6:$R6)/SUMPRODUCT(('Matriz Criterios'!$H$50:$V$50="X")*ISNUMBER('Registro Notas'!$D6:$R6))) | AV6: =AVERAGE(C6:AU6) | AW6: =COUNTIF(C6:AU6, ">=5")
A7: 2 | B7: Benítez Romero, Carlos | C7: =IF(SUMPRODUCT(('Matriz Criterios'!$H$6:$V$6="X")*ISNUMBER('Registro Notas'!$D7:$R7))=0, "-", SUMPRODUCT(('Matriz Criterios'!$H$6:$V$6="X")*ISNUMBER('Registro Notas'!$D7:$R7)*'Registro Notas'!$D7:$R7)/SUMPRODUCT(('Matriz Criterios'!$H$6:$V$6="X")*ISNUMBER('Registro Notas'!$D7:$R7))) | D7: =IF(SUMPRODUCT(('Matriz Criterios'!$H$7:$V$7="X")*ISNUMBER('Registro Notas'!$D7:$R7))=0, "-", SUMPRODUCT(('Matriz Criterios'!$H$7:$V$7="X")*ISNUMBER('Registro Notas'!$D7:$R7)*'Registro Notas'!$D7:$R7)/SUMPRODUCT(('Matriz Criterios'!$H$7:$V$7="X")*ISNUMBER('Registro Notas'!$D7:$R7))) | E7: =IF(SUMPRODUCT(('Matriz Criterios'!$H$8:$V$8="X")*ISNUMBER('Registro Notas'!$D7:$R7))=0, "-", SUMPRODUCT(('Matriz Criterios'!$H$8:$V$8="X")*ISNUMBER('Registro Notas'!$D7:$R7)*'Registro Notas'!$D7:$R7)/SUMPRODUCT(('Matriz Criterios'!$H$8:$V$8="X")*ISNUMBER('Registro Notas'!$D7:$R7))) | F7: =IF(SUMPRODUCT(('Matriz Criterios'!$H$9:$V$9="X")*ISNUMBER('Registro Notas'!$D7:$R7))=0, "-", SUMPRODUCT(('Matriz Criterios'!$H$9:$V$9="X")*ISNUMBER('Registro Notas'!$D7:$R7)*'Registro Notas'!$D7:$R7)/SUMPRODUCT(('Matriz Criterios'!$H$9:$V$9="X")*ISNUMBER('Registro Notas'!$D7:$R7))) | G7: =IF(SUMPRODUCT(('Matriz Criterios'!$H$10:$V$10="X")*ISNUMBER('Registro Notas'!$D7:$R7))=0, "-", SUMPRODUCT(('Matriz Criterios'!$H$10:$V$10="X")*ISNUMBER('Registro Notas'!$D7:$R7)*'Registro Notas'!$D7:$R7)/SUMPRODUCT(('Matriz Criterios'!$H$10:$V$10="X")*ISNUMBER('Registro Notas'!$D7:$R7))) | H7: =IF(SUMPRODUCT(('Matriz Criterios'!$H$11:$V$11="X")*ISNUMBER('Registro Notas'!$D7:$R7))=0, "-", SUMPRODUCT(('Matriz Criterios'!$H$11:$V$11="X")*ISNUMBER('Registro Notas'!$D7:$R7)*'Registro Notas'!$D7:$R7)/SUMPRODUCT(('Matriz Criterios'!$H$11:$V$11="X")*ISNUMBER('Registro Notas'!$D7:$R7))) | I7: =IF(SUMPRODUCT(('Matriz Criterios'!$H$12:$V$12="X")*ISNUMBER('Registro Notas'!$D7:$R7))=0, "-", SUMPRODUCT(('Matriz Criterios'!$H$12:$V$12="X")*ISNUMBER('Registro Notas'!$D7:$R7)*'Registro Notas'!$D7:$R7)/SUMPRODUCT(('Matriz Criterios'!$H$12:$V$12="X")*ISNUMBER('Registro Notas'!$D7:$R7))) | J7: =IF(SUMPRODUCT(('Matriz Criterios'!$H$13:$V$13="X")*ISNUMBER('Registro Notas'!$D7:$R7))=0, "-", SUMPRODUCT(('Matriz Criterios'!$H$13:$V$13="X")*ISNUMBER('Registro Notas'!$D7:$R7)*'Registro Notas'!$D7:$R7)/SUMPRODUCT(('Matriz Criterios'!$H$13:$V$13="X")*ISNUMBER('Registro Notas'!$D7:$R7))) | K7: =IF(SUMPRODUCT(('Matriz Criterios'!$H$14:$V$14="X")*ISNUMBER('Registro Notas'!$D7:$R7))=0, "-", SUMPRODUCT(('Matriz Criterios'!$H$14:$V$14="X")*ISNUMBER('Registro Notas'!$D7:$R7)*'Registro Notas'!$D7:$R7)/SUMPRODUCT(('Matriz Criterios'!$H$14:$V$14="X")*ISNUMBER('Registro Notas'!$D7:$R7))) | L7: =IF(SUMPRODUCT(('Matriz Criterios'!$H$15:$V$15="X")*ISNUMBER('Registro Notas'!$D7:$R7))=0, "-", SUMPRODUCT(('Matriz Criterios'!$H$15:$V$15="X")*ISNUMBER('Registro Notas'!$D7:$R7)*'Registro Notas'!$D7:$R7)/SUMPRODUCT(('Matriz Criterios'!$H$15:$V$15="X")*ISNUMBER('Registro Notas'!$D7:$R7))) | M7: =IF(SUMPRODUCT(('Matriz Criterios'!$H$16:$V$16="X")*ISNUMBER('Registro Notas'!$D7:$R7))=0, "-", SUMPRODUCT(('Matriz Criterios'!$H$16:$V$16="X")*ISNUMBER('Registro Notas'!$D7:$R7)*'Registro Notas'!$D7:$R7)/SUMPRODUCT(('Matriz Criterios'!$H$16:$V$16="X")*ISNUMBER('Registro Notas'!$D7:$R7))) | N7: =IF(SUMPRODUCT(('Matriz Criterios'!$H$17:$V$17="X")*ISNUMBER('Registro Notas'!$D7:$R7))=0, "-", SUMPRODUCT(('Matriz Criterios'!$H$17:$V$17="X")*ISNUMBER('Registro Notas'!$D7:$R7)*'Registro Notas'!$D7:$R7)/SUMPRODUCT(('Matriz Criterios'!$H$17:$V$17="X")*ISNUMBER('Registro Notas'!$D7:$R7))) | O7: =IF(SUMPRODUCT(('Matriz Criterios'!$H$18:$V$18="X")*ISNUMBER('Registro Notas'!$D7:$R7))=0, "-", SUMPRODUCT(('Matriz Criterios'!$H$18:$V$18="X")*ISNUMBER('Registro Notas'!$D7:$R7)*'Registro Notas'!$D7:$R7)/SUMPRODUCT(('Matriz Criterios'!$H$18:$V$18="X")*ISNUMBER('Registro Notas'!$D7:$R7))) | P7: =IF(SUMPRODUCT(('Matriz Criterios'!$H$19:$V$19="X")*ISNUMBER('Registro Notas'!$D7:$R7))=0, "-", SUMPRODUCT(('Matriz Criterios'!$H$19:$V$19="X")*ISNUMBER('Registro Notas'!$D7:$R7)*'Registro Notas'!$D7:$R7)/SUMPRODUCT(('Matriz Criterios'!$H$19:$V$19="X")*ISNUMBER('Registro Notas'!$D7:$R7))) | Q7: =IF(SUMPRODUCT(('Matriz Criterios'!$H$20:$V$20="X")*ISNUMBER('Registro Notas'!$D7:$R7))=0, "-", SUMPRODUCT(('Matriz Criterios'!$H$20:$V$20="X")*ISNUMBER('Registro Notas'!$D7:$R7)*'Registro Notas'!$D7:$R7)/SUMPRODUCT(('Matriz Criterios'!$H$20:$V$20="X")*ISNUMBER('Registro Notas'!$D7:$R7))) | R7: =IF(SUMPRODUCT(('Matriz Criterios'!$H$21:$V$21="X")*ISNUMBER('Registro Notas'!$D7:$R7))=0, "-", SUMPRODUCT(('Matriz Criterios'!$H$21:$V$21="X")*ISNUMBER('Registro Notas'!$D7:$R7)*'Registro Notas'!$D7:$R7)/SUMPRODUCT(('Matriz Criterios'!$H$21:$V$21="X")*ISNUMBER('Registro Notas'!$D7:$R7))) | S7: =IF(SUMPRODUCT(('Matriz Criterios'!$H$22:$V$22="X")*ISNUMBER('Registro Notas'!$D7:$R7))=0, "-", SUMPRODUCT(('Matriz Criterios'!$H$22:$V$22="X")*ISNUMBER('Registro Notas'!$D7:$R7)*'Registro Notas'!$D7:$R7)/SUMPRODUCT(('Matriz Criterios'!$H$22:$V$22="X")*ISNUMBER('Registro Notas'!$D7:$R7))) | T7: =IF(SUMPRODUCT(('Matriz Criterios'!$H$23:$V$23="X")*ISNUMBER('Registro Notas'!$D7:$R7))=0, "-", SUMPRODUCT(('Matriz Criterios'!$H$23:$V$23="X")*ISNUMBER('Registro Notas'!$D7:$R7)*'Registro Notas'!$D7:$R7)/SUMPRODUCT(('Matriz Criterios'!$H$23:$V$23="X")*ISNUMBER('Registro Notas'!$D7:$R7))) | U7: =IF(SUMPRODUCT(('Matriz Criterios'!$H$24:$V$24="X")*ISNUMBER('Registro Notas'!$D7:$R7))=0, "-", SUMPRODUCT(('Matriz Criterios'!$H$24:$V$24="X")*ISNUMBER('Registro Notas'!$D7:$R7)*'Registro Notas'!$D7:$R7)/SUMPRODUCT(('Matriz Criterios'!$H$24:$V$24="X")*ISNUMBER('Registro Notas'!$D7:$R7))) | V7: =IF(SUMPRODUCT(('Matriz Criterios'!$H$25:$V$25="X")*ISNUMBER('Registro Notas'!$D7:$R7))=0, "-", SUMPRODUCT(('Matriz Criterios'!$H$25:$V$25="X")*ISNUMBER('Registro Notas'!$D7:$R7)*'Registro Notas'!$D7:$R7)/SUMPRODUCT(('Matriz Criterios'!$H$25:$V$25="X")*ISNUMBER('Registro Notas'!$D7:$R7))) | W7: =IF(SUMPRODUCT(('Matriz Criterios'!$H$26:$V$26="X")*ISNUMBER('Registro Notas'!$D7:$R7))=0, "-", SUMPRODUCT(('Matriz Criterios'!$H$26:$V$26="X")*ISNUMBER('Registro Notas'!$D7:$R7)*'Registro Notas'!$D7:$R7)/SUMPRODUCT(('Matriz Criterios'!$H$26:$V$26="X")*ISNUMBER('Registro Notas'!$D7:$R7))) | X7: =IF(SUMPRODUCT(('Matriz Criterios'!$H$27:$V$27="X")*ISNUMBER('Registro Notas'!$D7:$R7))=0, "-", SUMPRODUCT(('Matriz Criterios'!$H$27:$V$27="X")*ISNUMBER('Registro Notas'!$D7:$R7)*'Registro Notas'!$D7:$R7)/SUMPRODUCT(('Matriz Criterios'!$H$27:$V$27="X")*ISNUMBER('Registro Notas'!$D7:$R7))) | Y7: =IF(SUMPRODUCT(('Matriz Criterios'!$H$28:$V$28="X")*ISNUMBER('Registro Notas'!$D7:$R7))=0, "-", SUMPRODUCT(('Matriz Criterios'!$H$28:$V$28="X")*ISNUMBER('Registro Notas'!$D7:$R7)*'Registro Notas'!$D7:$R7)/SUMPRODUCT(('Matriz Criterios'!$H$28:$V$28="X")*ISNUMBER('Registro Notas'!$D7:$R7))) | Z7: =IF(SUMPRODUCT(('Matriz Criterios'!$H$29:$V$29="X")*ISNUMBER('Registro Notas'!$D7:$R7))=0, "-", SUMPRODUCT(('Matriz Criterios'!$H$29:$V$29="X")*ISNUMBER('Registro Notas'!$D7:$R7)*'Registro Notas'!$D7:$R7)/SUMPRODUCT(('Matriz Criterios'!$H$29:$V$29="X")*ISNUMBER('Registro Notas'!$D7:$R7))) | AA7: =IF(SUMPRODUCT(('Matriz Criterios'!$H$30:$V$30="X")*ISNUMBER('Registro Notas'!$D7:$R7))=0, "-", SUMPRODUCT(('Matriz Criterios'!$H$30:$V$30="X")*ISNUMBER('Registro Notas'!$D7:$R7)*'Registro Notas'!$D7:$R7)/SUMPRODUCT(('Matriz Criterios'!$H$30:$V$30="X")*ISNUMBER('Registro Notas'!$D7:$R7))) | AB7: =IF(SUMPRODUCT(('Matriz Criterios'!$H$31:$V$31="X")*ISNUMBER('Registro Notas'!$D7:$R7))=0, "-", SUMPRODUCT(('Matriz Criterios'!$H$31:$V$31="X")*ISNUMBER('Registro Notas'!$D7:$R7)*'Registro Notas'!$D7:$R7)/SUMPRODUCT(('Matriz Criterios'!$H$31:$V$31="X")*ISNUMBER('Registro Notas'!$D7:$R7))) | AC7: =IF(SUMPRODUCT(('Matriz Criterios'!$H$32:$V$32="X")*ISNUMBER('Registro Notas'!$D7:$R7))=0, "-", SUMPRODUCT(('Matriz Criterios'!$H$32:$V$32="X")*ISNUMBER('Registro Notas'!$D7:$R7)*'Registro Notas'!$D7:$R7)/SUMPRODUCT(('Matriz Criterios'!$H$32:$V$32="X")*ISNUMBER('Registro Notas'!$D7:$R7))) | AD7: =IF(SUMPRODUCT(('Matriz Criterios'!$H$33:$V$33="X")*ISNUMBER('Registro Notas'!$D7:$R7))=0, "-", SUMPRODUCT(('Matriz Criterios'!$H$33:$V$33="X")*ISNUMBER('Registro Notas'!$D7:$R7)*'Registro Notas'!$D7:$R7)/SUMPRODUCT(('Matriz Criterios'!$H$33:$V$33="X")*ISNUMBER('Registro Notas'!$D7:$R7))) | AE7: =IF(SUMPRODUCT(('Matriz Criterios'!$H$34:$V$34="X")*ISNUMBER('Registro Notas'!$D7:$R7))=0, "-", SUMPRODUCT(('Matriz Criterios'!$H$34:$V$34="X")*ISNUMBER('Registro Notas'!$D7:$R7)*'Registro Notas'!$D7:$R7)/SUMPRODUCT(('Matriz Criterios'!$H$34:$V$34="X")*ISNUMBER('Registro Notas'!$D7:$R7))) | AF7: =IF(SUMPRODUCT(('Matriz Criterios'!$H$35:$V$35="X")*ISNUMBER('Registro Notas'!$D7:$R7))=0, "-", SUMPRODUCT(('Matriz Criterios'!$H$35:$V$35="X")*ISNUMBER('Registro Notas'!$D7:$R7)*'Registro Notas'!$D7:$R7)/SUMPRODUCT(('Matriz Criterios'!$H$35:$V$35="X")*ISNUMBER('Registro Notas'!$D7:$R7))) | AG7: =IF(SUMPRODUCT(('Matriz Criterios'!$H$36:$V$36="X")*ISNUMBER('Registro Notas'!$D7:$R7))=0, "-", SUMPRODUCT(('Matriz Criterios'!$H$36:$V$36="X")*ISNUMBER('Registro Notas'!$D7:$R7)*'Registro Notas'!$D7:$R7)/SUMPRODUCT(('Matriz Criterios'!$H$36:$V$36="X")*ISNUMBER('Registro Notas'!$D7:$R7))) | AH7: =IF(SUMPRODUCT(('Matriz Criterios'!$H$37:$V$37="X")*ISNUMBER('Registro Notas'!$D7:$R7))=0, "-", SUMPRODUCT(('Matriz Criterios'!$H$37:$V$37="X")*ISNUMBER('Registro Notas'!$D7:$R7)*'Registro Notas'!$D7:$R7)/SUMPRODUCT(('Matriz Criterios'!$H$37:$V$37="X")*ISNUMBER('Registro Notas'!$D7:$R7))) | AI7: =IF(SUMPRODUCT(('Matriz Criterios'!$H$38:$V$38="X")*ISNUMBER('Registro Notas'!$D7:$R7))=0, "-", SUMPRODUCT(('Matriz Criterios'!$H$38:$V$38="X")*ISNUMBER('Registro Notas'!$D7:$R7)*'Registro Notas'!$D7:$R7)/SUMPRODUCT(('Matriz Criterios'!$H$38:$V$38="X")*ISNUMBER('Registro Notas'!$D7:$R7))) | AJ7: =IF(SUMPRODUCT(('Matriz Criterios'!$H$39:$V$39="X")*ISNUMBER('Registro Notas'!$D7:$R7))=0, "-", SUMPRODUCT(('Matriz Criterios'!$H$39:$V$39="X")*ISNUMBER('Registro Notas'!$D7:$R7)*'Registro Notas'!$D7:$R7)/SUMPRODUCT(('Matriz Criterios'!$H$39:$V$39="X")*ISNUMBER('Registro Notas'!$D7:$R7))) | AK7: =IF(SUMPRODUCT(('Matriz Criterios'!$H$40:$V$40="X")*ISNUMBER('Registro Notas'!$D7:$R7))=0, "-", SUMPRODUCT(('Matriz Criterios'!$H$40:$V$40="X")*ISNUMBER('Registro Notas'!$D7:$R7)*'Registro Notas'!$D7:$R7)/SUMPRODUCT(('Matriz Criterios'!$H$40:$V$40="X")*ISNUMBER('Registro Notas'!$D7:$R7))) | AL7: =IF(SUMPRODUCT(('Matriz Criterios'!$H$41:$V$41="X")*ISNUMBER('Registro Notas'!$D7:$R7))=0, "-", SUMPRODUCT(('Matriz Criterios'!$H$41:$V$41="X")*ISNUMBER('Registro Notas'!$D7:$R7)*'Registro Notas'!$D7:$R7)/SUMPRODUCT(('Matriz Criterios'!$H$41:$V$41="X")*ISNUMBER('Registro Notas'!$D7:$R7))) | AM7: =IF(SUMPRODUCT(('Matriz Criterios'!$H$42:$V$42="X")*ISNUMBER('Registro Notas'!$D7:$R7))=0, "-", SUMPRODUCT(('Matriz Criterios'!$H$42:$V$42="X")*ISNUMBER('Registro Notas'!$D7:$R7)*'Registro Notas'!$D7:$R7)/SUMPRODUCT(('Matriz Criterios'!$H$42:$V$42="X")*ISNUMBER('Registro Notas'!$D7:$R7))) | AN7: =IF(SUMPRODUCT(('Matriz Criterios'!$H$43:$V$43="X")*ISNUMBER('Registro Notas'!$D7:$R7))=0, "-", SUMPRODUCT(('Matriz Criterios'!$H$43:$V$43="X")*ISNUMBER('Registro Notas'!$D7:$R7)*'Registro Notas'!$D7:$R7)/SUMPRODUCT(('Matriz Criterios'!$H$43:$V$43="X")*ISNUMBER('Registro Notas'!$D7:$R7))) | AO7: =IF(SUMPRODUCT(('Matriz Criterios'!$H$44:$V$44="X")*ISNUMBER('Registro Notas'!$D7:$R7))=0, "-", SUMPRODUCT(('Matriz Criterios'!$H$44:$V$44="X")*ISNUMBER('Registro Notas'!$D7:$R7)*'Registro Notas'!$D7:$R7)/SUMPRODUCT(('Matriz Criterios'!$H$44:$V$44="X")*ISNUMBER('Registro Notas'!$D7:$R7))) | AP7: =IF(SUMPRODUCT(('Matriz Criterios'!$H$45:$V$45="X")*ISNUMBER('Registro Notas'!$D7:$R7))=0, "-", SUMPRODUCT(('Matriz Criterios'!$H$45:$V$45="X")*ISNUMBER('Registro Notas'!$D7:$R7)*'Registro Notas'!$D7:$R7)/SUMPRODUCT(('Matriz Criterios'!$H$45:$V$45="X")*ISNUMBER('Registro Notas'!$D7:$R7))) | AQ7: =IF(SUMPRODUCT(('Matriz Criterios'!$H$46:$V$46="X")*ISNUMBER('Registro Notas'!$D7:$R7))=0, "-", SUMPRODUCT(('Matriz Criterios'!$H$46:$V$46="X")*ISNUMBER('Registro Notas'!$D7:$R7)*'Registro Notas'!$D7:$R7)/SUMPRODUCT(('Matriz Criterios'!$H$46:$V$46="X")*ISNUMBER('Registro Notas'!$D7:$R7))) | AR7: =IF(SUMPRODUCT(('Matriz Criterios'!$H$47:$V$47="X")*ISNUMBER('Registro Notas'!$D7:$R7))=0, "-", SUMPRODUCT(('Matriz Criterios'!$H$47:$V$47="X")*ISNUMBER('Registro Notas'!$D7:$R7)*'Registro Notas'!$D7:$R7)/SUMPRODUCT(('Matriz Criterios'!$H$47:$V$47="X")*ISNUMBER('Registro Notas'!$D7:$R7))) | AS7: =IF(SUMPRODUCT(('Matriz Criterios'!$H$48:$V$48="X")*ISNUMBER('Registro Notas'!$D7:$R7))=0, "-", SUMPRODUCT(('Matriz Criterios'!$H$48:$V$48="X")*ISNUMBER('Registro Notas'!$D7:$R7)*'Registro Notas'!$D7:$R7)/SUMPRODUCT(('Matriz Criterios'!$H$48:$V$48="X")*ISNUMBER('Registro Notas'!$D7:$R7))) | AT7: =IF(SUMPRODUCT(('Matriz Criterios'!$H$49:$V$49="X")*ISNUMBER('Registro Notas'!$D7:$R7))=0, "-", SUMPRODUCT(('Matriz Criterios'!$H$49:$V$49="X")*ISNUMBER('Registro Notas'!$D7:$R7)*'Registro Notas'!$D7:$R7)/SUMPRODUCT(('Matriz Criterios'!$H$49:$V$49="X")*ISNUMBER('Registro Notas'!$D7:$R7))) | AU7: =IF(SUMPRODUCT(('Matriz Criterios'!$H$50:$V$50="X")*ISNUMBER('Registro Notas'!$D7:$R7))=0, "-", SUMPRODUCT(('Matriz Criterios'!$H$50:$V$50="X")*ISNUMBER('Registro Notas'!$D7:$R7)*'Registro Notas'!$D7:$R7)/SUMPRODUCT(('Matriz Criterios'!$H$50:$V$50="X")*ISNUMBER('Registro Notas'!$D7:$R7))) | AV7: =AVERAGE(C7:AU7) | AW7: =COUNTIF(C7:AU7, ">=5")
